Traceback (most recent call last):
  File "C:\Users\fores\AppData\Local\Programs\Python\Python38\lib\site-packages\nbclient\client.py", line 778, in _async_poll_for_reply
    msg = await ensure_async(self.kc.shell_channel.get_msg(timeout=new_timeout))
  File "C:\Users\fores\AppData\Local\Programs\Python\Python38\lib\site-packages\jupyter_core\utils\__init__.py", line 198, in ensure_async
    result = await obj
  File "C:\Users\fores\AppData\Local\Programs\Python\Python38\lib\site-packages\jupyter_client\channels.py", line 313, in get_msg
    raise Empty
_queue.Empty

During handling of the above exception, another exception occurred:

Traceback (most recent call last):
  File "C:\Users\fores\AppData\Local\Programs\Python\Python38\lib\site-packages\jupyter_cache\executors\utils.py", line 58, in single_nb_execution
    executenb(
  File "C:\Users\fores\AppData\Local\Programs\Python\Python38\lib\site-packages\nbclient\client.py", line 1305, in execute
    return NotebookClient(nb=nb, resources=resources, km=km, **kwargs).execute()
  File "C:\Users\fores\AppData\Local\Programs\Python\Python38\lib\site-packages\jupyter_core\utils\__init__.py", line 165, in wrapped
    return loop.run_until_complete(inner)
  File "C:\Users\fores\AppData\Local\Programs\Python\Python38\lib\asyncio\base_events.py", line 616, in run_until_complete
    return future.result()
  File "C:\Users\fores\AppData\Local\Programs\Python\Python38\lib\site-packages\nbclient\client.py", line 705, in async_execute
    await self.async_execute_cell(
  File "C:\Users\fores\AppData\Local\Programs\Python\Python38\lib\site-packages\nbclient\client.py", line 1001, in async_execute_cell
    exec_reply = await self.task_poll_for_reply
  File "C:\Users\fores\AppData\Local\Programs\Python\Python38\lib\site-packages\nbclient\client.py", line 802, in _async_poll_for_reply
    error_on_timeout_execute_reply = await self._async_handle_timeout(timeout, cell)
  File "C:\Users\fores\AppData\Local\Programs\Python\Python38\lib\site-packages\nbclient\client.py", line 852, in _async_handle_timeout
    raise CellTimeoutError.error_from_timeout_and_cell(
nbclient.exceptions.CellTimeoutError: A cell timed out while it was being executed, after 30 seconds.
The message was: Cell execution timed out.
Here is a preview of the cell contents:
-------------------
['clear ', 'close all', '[s_real,s_imaginaria] = meshgrid([-5:0.3:5],[-20:0.5:20]);', 's = s_real+j*s_imaginaria; %Definición de la variable compleja s=real+imaginaria', 'Xs = @(s) (1)./(2.5*s.^2+3*s+350);  % Transformada de Laplace de la salida de un sistema']
...
["zlabel('|X(s)|');", '% Se especifica un ángulo de mejor visualización. ', 'view(gca,[23.5,38]);', "set(gca,'fontsize',20);", "%set(gca,'fontname','Times New Roman','FontWeight','Bold');"]
-------------------

